<robot name="test_robot">

  <link name="world"></link>

  <link name="base_link">
	<visual>
        <origin xyz="0 0 0.048"/>
         <geometry>
          <mesh filename="package://my_arm_xacro/meshes/link1-base.stl" scale ="0.001 0.001 0.001"/>
         </geometry>
        </visual>
        <collision>
         <geometry>
          <mesh filename="package://my_arm_xacro/meshes/link1-base.stl" scale ="0.001 0.001 0.001"/>
         </geometry>
        </collision>
  </link>

  <link name="link2">
	<visual>
    <origin xyz="0 0 0.041"/>
         <geometry>
          <mesh filename="package://my_arm_xacro/meshes/link2.stl" scale ="0.001 0.001 0.001"/>
         </geometry>
        </visual>
        <collision>
         <geometry>
          <mesh filename="package://my_arm_xacro/meshes/link2.stl" scale ="0.001 0.001 0.001"/>
         </geometry>
        </collision>
  </link>

  <link name="link3">
	<visual>
    <origin xyz="0 0.01 0.075"/>
         <geometry>
          <mesh filename="package://my_arm_xacro/meshes/link3.stl" scale ="0.001 0.001 0.001"/>
         </geometry>
        </visual>
        <collision>
         <geometry>
          <mesh filename="package://my_arm_xacro/meshes/link3.stl" scale ="0.001 0.001 0.001"/>
         </geometry>
        </collision>
  </link>

  <link name="link4">
	<visual>
    <origin xyz="-0.0275 -0.0385 0.025"/>
         <geometry>
          <mesh filename="package://my_arm_xacro/meshes/link4.stl" scale ="0.001 0.001 0.001"/>
         </geometry>
        </visual>
        <collision>
         <geometry>
          <mesh filename="package://my_arm_xacro/meshes/link4.stl" scale ="0.001 0.001 0.001"/>
         </geometry>
        </collision>
  </link>

  <link name="link5">
	<visual>
    <origin xyz="0.065 0 0.005"/>
         <geometry>
          <mesh filename="package://my_arm_xacro/meshes/link5.stl" scale ="0.001 0.001 0.001"/>
         </geometry>
        </visual>
        <collision>
         <geometry>
          <mesh filename="package://my_arm_xacro/meshes/link5.stl" scale ="0.001 0.001 0.001"/>
         </geometry>
        </collision>
  </link>

  <link name="link6">
	<visual>
    <origin xyz="0 0 0"/>
         <geometry>
          <mesh filename="package://my_arm_xacro/meshes/link6.stl" scale ="0.001 0.001 0.001"/>
         </geometry>
        </visual>
        <collision>
         <geometry>
          <mesh filename="package://my_arm_xacro/meshes/link6.stl" scale ="0.001 0.001 0.001"/>
         </geometry>
        </collision>
  </link>

  <link name="link7">
	<visual>
    <origin xyz="0.0075 0 0"/>
         <geometry>
          <mesh filename="package://my_arm_xacro/meshes/link7.stl" scale ="0.001 0.001 0.001"/>
         </geometry>
        </visual>
        <collision>
         <geometry>
          <mesh filename="package://my_arm_xacro/meshes/link7.stl" scale ="0.001 0.001 0.001"/>
         </geometry>
        </collision>
  </link>

  <joint name="base_joint" type="fixed">
    <parent link="world"/>
    <child link="base_link"/>
  </joint>

  <joint name="joint1" type="revolute">
    <axis xyz="0 0 -1" />
    <limit effort="100.0" lower="-3.141593" upper="3.141593" velocity="1.0" />
    <origin xyz="0 0 0.096"/>
    <parent link="base_link"/>
    <child link="link2"/>
  </joint>

  <joint name="joint2" type="revolute">
    <axis xyz="0 -1 0" />
    <limit effort="100.0" lower="-2" upper="2" velocity="1.0" />
    <origin xyz="0 0.05 0.041" rpy="0 0 0" />
    <parent link="link2"/>
    <child link="link3"/>
  </joint>

  <joint name="joint3" type="revolute">
    <axis xyz="0 -1 0" />
    <limit effort="100.0" lower="-1.3" upper="1" velocity="1.0" />
    <origin xyz="0 0 0.15" rpy="0 0 0" />
    <parent link="link3"/>
    <child link="link4"/>
  </joint>

  <joint name="joint4" type="revolute">
    <axis xyz="-1 0 0" />
    <limit effort="100.0" lower="-3.141593" upper="3.141593" velocity="1.0" />
    <origin xyz="0.018 -0.05 0.0495" rpy="0 0 0" />
    <parent link="link4"/>
    <child link="link5"/>
  </joint>

  <joint name="joint5" type="revolute">
    <axis xyz="0 0 1" />
    <limit effort="100.0" lower="-1.570796" upper="1.570796" velocity="1.0" />
    <origin xyz="0.115 0 0" rpy="0 0 0" />
    <parent link="link5"/>
    <child link="link6"/>
  </joint>

  <joint name="joint6" type="revolute">
    <axis xyz="-1 0 0" />
    <limit effort="100.0" lower="-3.141593" upper="3.141593" velocity="1.0" />
    <origin xyz="0.008 0 0" rpy="0 0 0" />
    <parent link="link6"/>
    <child link="link7"/>
  </joint>

</robot>
